<?xml version="1.0" ?>
<!-- =================================================================================== -->
<!-- |    Autogenerated by xacro from ../mbot_simulator/models/mbot.urdf.xacro         | -->
<!-- |    EDITING THIS FILE BY HAND IS NOT RECOMMENDED                                 | -->
<!-- =================================================================================== -->
<robot name="cyton_gamma_1500" xmlns:xacro="http://www.ros.org/wiki/xacro">
  <link name="arm_base_link">
    <visual>
      <origin rpy="0 0 0" xyz="0 0 0"/>
      <geometry>
        <mesh filename="package://mbot_simulator/meshes/base.dae"/>
      </geometry>
    </visual>
    <collision>
      <origin rpy="0 0 0" xyz="0 0 0"/>
      <geometry>
        <mesh filename="package://mbot_simulator/meshes/base.dae"/>
      </geometry>
    </collision>
  </link>
  <joint name="shoulder_roll_joint" type="revolute">
    <parent link="arm_base_link"/>
    <child link="shoulder_roll"/>
    <origin rpy="0 0 0" xyz="0 0 0.05315"/>
    <limit effort="100.0" lower="-2.618" upper="2.618" velocity="1.0"/>
    <axis xyz="0 0 1"/>
  </joint>
  <link name="shoulder_roll">
    <visual>
      <origin rpy="1.5708 0 0.384" xyz="0 0 0"/>
      <geometry>
        <mesh filename="package://mbot_simulator/meshes/shoulder_roll.dae"/>
      </geometry>
    </visual>
          <collision>
      <origin rpy="1.5708 0 0.384" xyz="0 0 0"/>
      <geometry>
        <mesh filename="package://mbot_simulator/meshes/shoulder_roll.dae"/>
      </geometry>
    </collision>
  </link>
  <joint name="shoulder_pitch_joint" type="revolute">
    <parent link="shoulder_roll"/>
    <child link="shoulder_pitch"/>
    <origin rpy="0 0 0" xyz="0.0205 0 0.12435"/>
    <limit effort="100.0" lower="-1.8326" upper="1.8326" velocity="1.0"/>
    <axis xyz="1 0 0"/>
  </joint>
  <link name="shoulder_pitch">
    <visual>
      <origin rpy="1.5708 0 0" xyz="0 0 0"/>
      <geometry>
        <mesh filename="package://mbot_simulator/meshes/shoulder_pitch.dae"/>
      </geometry>
    </visual>
          <collision>
      <origin rpy="1.5708 0 0" xyz="0 0 0"/>
      <geometry>
        <mesh filename="package://mbot_simulator/meshes/shoulder_pitch.dae"/>
      </geometry>
    </collision>
  </link>
  <joint name="shoulder_yaw_joint" type="revolute">
    <parent link="shoulder_pitch"/>
    <child link="shoulder_yaw"/>
    <origin rpy="0 0 0" xyz="-0.0215 -0.0205 0.1255"/>
    <limit effort="100.0" lower="-1.8326" upper="1.8326" velocity="1.0"/>
    <axis xyz="0 -1 0"/>
  </joint>
  <link name="shoulder_yaw">
    <visual>
      <origin rpy="1.5708 0 -1.5708" xyz="0 0 0.0"/>
      <geometry>
        <mesh filename="package://mbot_simulator/meshes/shoulder_yaw.dae"/>
      </geometry>
    </visual>
       <collision>
      <origin rpy="1.5708 0 -1.5708" xyz="0 0 0.0"/>
      <geometry>
        <mesh filename="package://mbot_simulator/meshes/shoulder_yaw.dae"/>
      </geometry>
    </collision>
  </link>
  <joint name="elbow_pitch_joint" type="revolute">
    <parent link="shoulder_yaw"/>
    <child link="elbow_pitch"/>
    <origin rpy="0 0 0" xyz="0.018 0.0206 0.1158"/>
    <limit effort="100.0" lower="-1.8326" upper="1.8326" velocity="1.0"/>
    <axis xyz="1 0 0"/>
  </joint>
  <link name="elbow_pitch">
    <visual>
      <origin rpy="1.5708 0 3.1416" xyz="0 0 0"/>
      <geometry>
        <mesh filename="package://mbot_simulator/meshes/elbow_pitch.dae"/>
      </geometry>
    </visual>
    <collision>
      <origin rpy="1.5708 0 3.1416" xyz="0 0 0"/>
      <geometry>
        <mesh filename="package://mbot_simulator/meshes/elbow_pitch.dae"/>
      </geometry>
    </collision>
  </link>
  <joint name="elbow_yaw_joint" type="revolute">
    <parent link="elbow_pitch"/>
    <child link="elbow_yaw"/>
    <origin rpy="0 0 0" xyz="-0.0171 -0.018 0.09746"/>
    <limit effort="100.0" lower="-1.8326" upper="1.8326" velocity="1.0"/>
    <axis xyz="0 -1 0"/>
  </joint>
  <link name="elbow_yaw">
    <visual>
      <origin rpy="1.5708 0 1.5708" xyz="0 0 0"/>
      <geometry>
        <mesh filename="package://mbot_simulator/meshes/elbow_yaw.dae"/>
      </geometry>
    </visual>
       <collision>
      <origin rpy="1.5708 0 1.5708" xyz="0 0 0"/>
      <geometry>
        <mesh filename="package://mbot_simulator/meshes/elbow_yaw.dae"/>
      </geometry>
    </collision>
  </link>
  <joint name="wrist_pitch_joint" type="revolute">
    <parent link="elbow_yaw"/>
    <child link="wrist_pitch"/>
    <origin rpy="0 0 0" xyz="0.02626 0.018 0.0718"/>
    <limit effort="100.0" lower="-1.8326" upper="1.8326" velocity="1.0"/>
    <axis xyz="1 0 0"/>
  </joint>
  <link name="wrist_pitch">
    <visual>
      <origin rpy="1.5708 0 1.5708" xyz="0 0 0"/>
      <geometry>
        <mesh filename="package://mbot_simulator/meshes/wrist_pitch.dae"/>
      </geometry>
    </visual>
    <collision>
      <origin rpy="1.5708 0 1.5708" xyz="0 0 0"/>
      <geometry>
        <mesh filename="package://mbot_simulator/meshes/wrist_pitch.dae"/>
      </geometry>
    </collision>
  </link>
  <joint name="wrist_roll_joint" type="revolute">
    <parent link="wrist_pitch"/>
    <child link="wrist_roll"/>
    <origin rpy="0 0 0" xyz="-0.026255 0 0.051425"/>
    <limit effort="100.0" lower="-2.61799" upper="2.61799" velocity="1.0"/>
    <axis xyz="0 0 1"/>
  </joint>
  <link name="wrist_roll">
    <visual>
      <origin rpy="3.1416 0 -1.5708" xyz="0 0 0"/>
      <geometry>
        <mesh filename="package://mbot_simulator/meshes/wrist_roll.dae"/>
      </geometry>
    </visual>
    <collision>
      <!--origin rpy="3.1416 0 -1.5708" xyz="0 0 0"/-->
      <origin rpy="3.1416 0 -1.5708" xyz="0 0 0.05"/>
      <geometry>
        <!--mesh filename="package://mbot_simulator/meshes/wrist_roll.dae"/-->
        <box size="0.06 0.06 0.2"/>
      </geometry>
    </collision>
  </link>
  <joint name="gripper_joint" type="prismatic">
    <parent link="wrist_roll"/>
    <child link="gripper_finger1"/>
    <origin rpy="0 0 0" xyz="-0.01331 0.00485 0.077225"/>
    <limit effort="100.0" lower="-0.008" upper="0.008" velocity="1.0"/>
    <axis xyz="1 0 0"/>
  </joint>
  <link name="gripper_finger1">
    <visual>
      <origin rpy="0 0 0" xyz="0 0 0"/>
      <geometry>
        <mesh filename="package://mbot_simulator/meshes/gripper_finger1.dae"/>
      </geometry>
    </visual>
    <!--collision>
      <origin rpy="0 0 0" xyz="0 0 0"/>
      <geometry>
        <mesh filename="package://mbot_simulator/meshes/gripper_finger1.dae"/>
      </geometry>
    </collision-->
  </link>
  <joint name="gripper_joint2" type="prismatic">
    <parent link="wrist_roll"/>
    <child link="gripper_finger2"/>
    <origin rpy="0 0 0" xyz="0.0098 0.00485 0.077225"/>
    <limit effort="100.0" lower="-0.008" upper="0.008" velocity="1.0"/>
    <mimic joint="gripper_joint" multiplier="-1"/>
    <axis xyz="1 0 0"/>
  </joint>
  <link name="gripper_finger2">
    <visual>
      <origin rpy="0 0 0" xyz="0 0 0"/>
      <geometry>
        <mesh filename="package://mbot_simulator/meshes/gripper_finger2.dae"/>
      </geometry>
    </visual>
    <!--collision>
      <origin rpy="0 0 0" xyz="0 0 0"/>
      <geometry>
        <mesh filename="package://mbot_simulator/meshes/gripper_finger2.dae"/>
      </geometry>
    </collision-->
  </link>
  <joint name="virtual_endeffector_joint" type="fixed">
    <parent link="wrist_roll"/>
    <child link="virtual_endeffector"/>
    <origin rpy="0 0 0" xyz="-0.002316 0.0079 0.079425"/>
  </joint>
  <link name="virtual_endeffector">
    <visual>
      <origin rpy="0 0 0" xyz="0 0 0"/>
      <geometry>
        <sphere radius="0.002"/>
      </geometry>
      <material name="grey">
        <color rgba="0.7 0.7 0.7 0.8"/>
      </material>
    </visual>
  </link>
  <link name="mbot_base_link"/>
  <link name="mbot_body_link">
    <visual>
      <geometry>
        <mesh filename="package://mbot_simulator/meshes/mbot_body.dae"/>
      </geometry>
      <origin rpy="1.57079632679 0 1.57079632679" xyz="0 0 0.025"/>
    </visual>
    <collision>
      <geometry>
        <mesh filename="package://mbot_simulator/meshes/mbot_body.dae"/>
      </geometry>
      <origin rpy="1.57079632679 0 1.57079632679" xyz="0 0 0.025"/>
    </collision>
    <inertial>
      <mass value="50.0"/>
      <origin xyz="0.0 0.0 0.0"/>
      <inertia ixx="1.0" ixy="0.0" ixz="0.0" iyy="1.0" iyz="0.0" izz="1.0"/>
    </inertial>
  </link>
  <link name="mbot_head_link">
    <visual>
      <geometry>
        <mesh filename="package://mbot_simulator/meshes/mbot_head.dae"/>
      </geometry>
      <origin rpy="1.57079632679 0 1.57079632679" xyz="-0.05 0 0"/>
    </visual>
    <!--collision>
      <geometry>
        <mesh filename="package://mbot_simulator/meshes/mbot_head.dae"/>
      </geometry>
      <origin rpy="1.57079632679 0 1.57079632679" xyz="-0.05 0 0"/>
    </collision-->
    <collision>
      <origin xyz="0.0 0.0 1.0"/>
      <geometry>
        <box size="0.48 0.48 0.4"/>
      </geometry>
    </collision>
    <inertial>
      <mass value="50.0"/>
      <origin xyz="0.0 0.0 0.0"/>
      <inertia ixx="1.0" ixy="0.0" ixz="0.0" iyy="1.0" iyz="0.0" izz="1.0"/>
    </inertial>
  </link>
  <joint name="mbot_main_joint" type="fixed">
    <parent link="mbot_base_link"/>
    <child link="mbot_body_link"/>
    <origin rpy="0 0 0" xyz="0 0 0"/>
  </joint>
  <joint name="mbot_head_joint" type="revolute">
    <parent link="mbot_body_link"/>
    <child link="mbot_head_link"/>
    <limit effort="100.0" lower="-1.57079632679" upper="1.57079632679" velocity="1.0"/>
    <axis xyz="0 0 1"/>
    <origin rpy="0 0 0" xyz="0.05 0 0"/>
  </joint>
  <joint name="body_to_arm_struct_joint" type="fixed">
    <parent link="mbot_body_link"/>
    <child link="mbot_arm_link"/>
    <origin rpy="-1.57079632679 -3.14159265359 0" xyz="0.04 0.101 0.633"/>
  </joint>
  <joint name="arm_struct_to_cyton_base_joint" type="fixed">
    <parent link="mbot_arm_link"/>
    <child link="arm_base_link"/>
    <origin rpy="0 0.1 -1.08210413624" xyz="0.0 0.0 0.0"/>
  </joint>
  <link name="mbot_arm_link">
    <inertial>
      <mass value="0.1"/>
      <origin xyz="0.0 0.0 0.0"/>
      <inertia ixx="1.0" ixy="0.0" ixz="0.0" iyy="1.0" iyz="0.0" izz="1.0"/>
    </inertial>
  </link>
  <link name="hokuyo_front_link">
    <visual>
      <geometry>
        <mesh filename="package://mbot_simulator/meshes/hokuyo.dae"/>
      </geometry>
    </visual>
    <inertial>
      <mass value="0.1"/>
      <origin xyz="0.0 0.0 0.0"/>
      <inertia ixx="1.0" ixy="0.0" ixz="0.0" iyy="1.0" iyz="0.0" izz="1.0"/>
    </inertial>
  </link>
  <link name="hokuyo_back_link">
    <visual>
      <geometry>
        <mesh filename="package://mbot_simulator/meshes/hokuyo.dae"/>
      </geometry>
    </visual>
    <inertial>
      <mass value="0.1"/>
      <origin xyz="0.0 0.0 0.0"/>
      <inertia ixx="1.0" ixy="0.0" ixz="0.0" iyy="1.0" iyz="0.0" izz="1.0"/>
    </inertial>
  </link>
  <link name="kinect_model_link">
    <inertial>
      <mass value="0.1"/>
      <origin xyz="0.0 0.0 0.0"/>
      <inertia ixx="1.0" ixy="0.0" ixz="0.0" iyy="1.0" iyz="0.0" izz="1.0"/>
    </inertial>
  </link>
  <link name="asus_xtion_model_link">
    <inertial>
      <mass value="0.1"/>
      <origin xyz="0.0 0.0 0.0"/>
      <inertia ixx="1.0" ixy="0.0" ixz="0.0" iyy="1.0" iyz="0.0" izz="1.0"/>
    </inertial>
  </link>
  <joint name="mbot_to_hokuyo_front_joint" type="fixed">
    <parent link="mbot_body_link"/>
    <child link="hokuyo_front_link"/>
    <origin rpy="0 0 0" xyz="0.2895 0 0.1365"/>
  </joint>
  <joint name="mbot_to_hokuyo_back_joint" type="fixed">
    <parent link="mbot_body_link"/>
    <child link="hokuyo_back_link"/>
    <origin rpy="3.14159265359 0 0" xyz="-0.275 0 0.145"/>
  </joint>
  <joint name="mbot_head_to_kinect_joint" type="fixed">
    <parent link="mbot_head_link"/>
    <child link="kinect_model_link"/>
    <origin rpy="0 0 0" xyz="0.155 0 0.92"/>
  </joint>
  <joint name="mbot_head_to_asus_xtion_joint" type="fixed">
    <parent link="mbot_head_link"/>
    <child link="asus_xtion_model_link"/>
    <origin rpy="0 0.785398163398 0" xyz="0.135 0 0.78"/>
  </joint>
</robot>
