<?xml version="1.0" ?>
<!-- =================================================================================== -->
<!-- |    This document was autogenerated by xacro from mbot.urdf.xacro                | -->
<!-- |    EDITING THIS FILE BY HAND IS NOT RECOMMENDED                                 | -->
<!-- =================================================================================== -->
<robot name="mbot" xmlns:xacro="http://www.ros.org/wiki/xacro">
  <link name="mbot_base_link">
    <visual>
      <geometry>
        <mesh filename="package://mbot_simulator/meshes/mbot_body.dae"/>
      </geometry>
      <origin rpy="1.57079632679 0 1.57079632679" xyz="0 0 0.025"/>
    </visual>
    <collision>
      <geometry>
        <mesh filename="package://mbot_simulator/meshes/mbot_body.dae"/>
      </geometry>
      <origin rpy="1.57079632679 0 1.57079632679" xyz="0 0 0.025"/>
    </collision>
    <inertial>
      <mass value="50.0"/>
      <origin xyz="0.0 0.0 0.0"/>
      <inertia ixx="1.0" ixy="0.0" ixz="0.0" iyy="1.0" iyz="0.0" izz="1.0"/>
    </inertial>
  </link>
  <link name="mbot_head_link">
    <visual>
      <geometry>
        <mesh filename="package://mbot_simulator/meshes/mbot_head.dae"/>
      </geometry>
      <origin rpy="1.57079632679 0 1.57079632679" xyz="-0.05 0 0"/>
    </visual>
    <collision>
      <geometry>
        <mesh filename="package://mbot_simulator/meshes/mbot_head.dae"/>
      </geometry>
      <origin rpy="1.57079632679 0 1.57079632679" xyz="-0.05 0 0"/>
    </collision>
    <inertial>
      <mass value="50.0"/>
      <origin xyz="0.0 0.0 0.0"/>
      <inertia ixx="1.0" ixy="0.0" ixz="0.0" iyy="1.0" iyz="0.0" izz="1.0"/>
    </inertial>
  </link>
  <joint name="mbot_head_joint" type="revolute">
    <parent link="mbot_base_link"/>
    <child link="mbot_head_link"/>
    <limit effort="100.0" lower="-1.57079632679" upper="1.57079632679" velocity="1.0"/>
    <axis xyz="0 0 1"/>
    <origin xyz="0.05 0 0"/>
  </joint>
</robot>
